<?xml version="1.0" encoding="utf-8"?>
<robot name="cuoiky">
  <!-- Base Link -->
  <link name="base_link">
    <inertial>
      <origin xyz="0.00231 0 -0.01278" rpy="0 0 0" />
      <mass value="1.015" />
      <inertia ixx="0.00219" ixy="0" ixz="-0.000042" iyy="0.00334" iyz="0" izz="0.00523" />
    </inertial>
    <visual>
      <origin xyz="0 0 0" rpy="0 0 0" />
      <geometry>
        <mesh filename="package://cuoiky/meshes/base_link.STL" />
      </geometry>
      <material name="default">
        <color rgba="0.792 0.819 0.933 1" />
      </material>
    </visual>
    <collision>
      <origin xyz="0 0 0" rpy="0 0 0" />
      <geometry>
        <mesh filename="package://cuoiky/meshes/base_link.STL" />
      </geometry>
    </collision>
  </link>

  <!-- Xoay Link -->
  <link name="xoay_link">
    <inertial>
      <origin xyz="0.01018 0 0.03729" rpy="0 0 0" />
      <mass value="0.05157" />
      <inertia ixx="0.0000316" ixy="0" ixz="-0.0000119" iyy="0.0000472" iyz="0" izz="0.0000209" />
    </inertial>
    <visual>
      <origin xyz="0 0 0" rpy="0 0 0" />
      <geometry>
        <mesh filename="package://cuoiky/meshes/xoay_link.STL" />
      </geometry>
      <material name="default">
        <color rgba="0.792 0.819 0.933 1" />
      </material>
    </visual>
    <collision>
      <origin xyz="0 0 0" rpy="0 0 0" />
      <geometry>
        <mesh filename="package://cuoiky/meshes/xoay_link.STL" />
      </geometry>
    </collision>
  </link>
  <joint name="xoay_joint" type="revolute">
    <origin xyz="0.021 0 0.04" rpy="0 0 0" />
    <parent link="base_link" />
    <child link="xoay_link" />
    <axis xyz="0 0 -1" />
    <limit lower="-3.14" upper="3.14" effort="100" velocity="10" />
  </joint>

  <!-- Tien Link -->
  <link name="tien_link">
    <inertial>
      <origin xyz="0 0 -0.025" rpy="0 0 0" />
      <mass value="0.005" />
      <inertia ixx="0.00000108" ixy="0" ixz="0" iyy="0.00000108" iyz="0" izz="0.000000083" />
    </inertial>
    <visual>
      <origin xyz="0 0 0" rpy="0 0 0" />
      <geometry>
        <mesh filename="package://cuoiky/meshes/tien_link.STL" />
      </geometry>
      <material name="default">
        <color rgba="0.792 0.819 0.933 1" />
      </material>
    </visual>
    <collision>
      <origin xyz="0 0 0" rpy="0 0 0" />
      <geometry>
        <mesh filename="package://cuoiky/meshes/tien_link.STL" />
      </geometry>
    </collision>
  </link>
  <joint name="tien_joint" type="prismatic">
    <origin xyz="0.06 0 0.06" rpy="1.571 0 1.571" />
    <parent link="xoay_link" />
    <child link="tien_link" />
    <axis xyz="0 0 -1" />
    <limit lower="-0.05" upper="0" effort="100" velocity="1" />
  </joint>

  <!-- TT Link -->
  <link name="tt_link">
    <inertial>
      <origin xyz="0 0 -0.01544" rpy="0 0 0" />
      <mass value="0.04581" />
      <inertia ixx="0.0000188" ixy="0" ixz="0" iyy="0.0000188" iyz="0" izz="0.0000326" />
    </inertial>
    <visual>
      <origin xyz="0 0 0" rpy="0 0 0" />
      <geometry>
        <mesh filename="package://cuoiky/meshes/tt_link.STL" />
      </geometry>
      <material name="default">
        <color rgba="0.251 0.251 0.251 1" />
      </material>
    </visual>
    <collision>
      <origin xyz="0 0 0" rpy="0 0 0" />
      <geometry>
        <mesh filename="package://cuoiky/meshes/tt_link.STL" />
      </geometry>
    </collision>
  </link>
  <joint name="tt_joint" type="continuous">
    <origin xyz="0.071 0.089 -0.017" rpy="1.571 0 0" />
    <parent link="base_link" />
    <child link="tt_link" />
    <axis xyz="0 0 1" />
  </joint>

  <!-- TP Link -->
  <link name="tp_link">
    <inertial>
      <origin xyz="0 0 0.01544" rpy="0 0 0" />
      <mass value="0.04581" />
      <inertia ixx="0.0000188" ixy="0" ixz="0" iyy="0.0000188" iyz="0" izz="0.0000326" />
    </inertial>
    <visual>
      <origin xyz="0 0 0" rpy="0 0 0" />
      <geometry>
        <mesh filename="package://cuoiky/meshes/tp_link.STL" />
      </geometry>
      <material name="default">
        <color rgba="0.251 0.251 0.251 1" />
      </material>
    </visual>
    <collision>
      <origin xyz="0 0 0" rpy="0 0 0" />
      <geometry>
        <mesh filename="package://cuoiky/meshes/tp_link.STL" />
      </geometry>
    </collision>
  </link>
  <joint name="tp_joint" type="continuous">
    <origin xyz="0.071 -0.089 -0.017" rpy="1.571 0 0" />
    <parent link="base_link" />
    <child link="tp_link" />
    <axis xyz="0 0 1" />
  </joint>

  <!-- SP Link -->
  <link name="sp_link">
    <inertial>
      <origin xyz="0 0 0.01544" rpy="0 0 0" />
      <mass value="0.04581" />
      <inertia ixx="0.0000188" ixy="0" ixz="0" iyy="0.0000188" iyz="0" izz="0.0000326" />
    </inertial>
    <visual>
      <origin xyz="0 0 0" rpy="0 0 0" />
      <geometry>
        <mesh filename="package://cuoiky/meshes/sp_link.STL" />
      </geometry>
      <material name="default">
        <color rgba="0.251 0.251 0.251 1" />
      </material>
    </visual>
    <collision>
      <origin xyz="0 0 0" rpy="0 0 0" />
      <geometry>
        <mesh filename="package://cuoiky/meshes/sp_link.STL" />
      </geometry>
    </collision>
  </link>
  <joint name="sp_joint" type="continuous">
    <origin xyz="-0.069 -0.089 -0.017" rpy="1.571 0 0" />
    <parent link="base_link" />
    <child link="sp_link" />
    <axis xyz="0 0 -1" />
  </joint>

  <!-- ST Link -->
  <link name="st_link">
    <inertial>
      <origin xyz="0 0 -0.01544" rpy="0 0 0" />
      <mass value="0.04581" />
      <inertia ixx="0.0000188" ixy="0" ixz="0" iyy="0.0000188" iyz="0" izz="0.0000326" />
    </inertial>
    <visual>
      <origin xyz="0 0 0" rpy="0 0 0" />
      <geometry>
        <mesh filename="package://cuoiky/meshes/st_link.STL" />
      </geometry>
      <material name="default">
        <color rgba="0.251 0.251 0.251 1" />
      </material>
    </visual>
    <collision>
      <origin xyz="0 0 0" rpy="0 0 0" />
      <geometry>
        <mesh filename="package://cuoiky/meshes/st_link.STL" />
      </geometry>
    </collision>
  </link>
  <joint name="st_joint" type="continuous">
    <origin xyz="-0.069 0.089 -0.017" rpy="1.571 0 0" />
    <parent link="base_link" />
    <child link="st_link" />
    <axis xyz="0 0 -1" />
  </joint>

  <!-- Camera Link -->
  <link name="camera_link">
    <inertial>
      <origin xyz="0.005 0 0" rpy="0 0 0" />
      <mass value="0.001" />
      <inertia ixx="0.0000000167" ixy="0" ixz="0" iyy="0.0000000167" iyz="0" izz="0.0000000167" />
    </inertial>
    <visual>
      <origin xyz="0 0 0" rpy="0 0 0" />
      <geometry>
        <mesh filename="package://cuoiky/meshes/camera_link.STL" />
      </geometry>
      <material name="default">
        <color rgba="0.792 0.819 0.933 1" />
      </material>
    </visual>
    <collision>
      <origin xyz="0 0 0" rpy="0 0 0" />
      <geometry>
        <mesh filename="package://cuoiky/meshes/camera_link.STL" />
      </geometry>
    </collision>
  </link>
  <joint name="camera_joint" type="fixed">
    <origin xyz="0.101 0.003 -0.005" rpy="1.571 0 0" />
    <parent link="base_link" />
    <child link="camera_link" />
  </joint>

  <!-- IMU Link -->
  <link name="imu_link">
    <inertial>
      <origin xyz="-0.005 0 0" rpy="0 0 0" />
      <mass value="0.001" />
      <inertia ixx="0.0000000167" ixy="0" ixz="0" iyy="0.0000000167" iyz="0" izz="0.0000000167" />
    </inertial>
    <visual>
      <origin xyz="0 0 0" rpy="0 0 0" />
      <geometry>
        <mesh filename="package://cuoiky/meshes/imu_link.STL" />
      </geometry>
      <material name="default">
        <color rgba="0.792 0.819 0.933 1" />
      </material>
    </visual>
    <collision>
      <origin xyz="0 0 0" rpy="0 0 0" />
      <geometry>
        <mesh filename="package://cuoiky/meshes/imu_link.STL" />
      </geometry>
    </collision>
  </link>
  <joint name="imu_joint" type="fixed">
    <origin xyz="0.041 -0.001 0.035" rpy="1.571 0 3.142" />
    <parent link="base_link" />
    <child link="imu_link" />
  </joint>

  <!-- Gazebo IMU Plugin -->
  <gazebo reference="imu_link">
    <plugin name="imu_plugin" filename="libgazebo_ros_imu.so">
      <ros>
        <namespace>/</namespace>
      </ros>
      <alwaysOn>true</alwaysOn>
      <updateRate>50.0</updateRate>
      <topicName>/imu/data</topicName>
    </plugin>
  </gazebo>

  <!-- Gazebo Camera Plugin -->
  <gazebo reference="camera_link">
    <plugin name="camera_plugin" filename="libgazebo_ros_camera.so">
      <alwaysOn>true</alwaysOn>
      <updateRate>30.0</updateRate>
      <cameraName>camera1</cameraName>
      <imageTopicName>/camera1/image_raw</imageTopicName>
      <cameraInfoTopicName>/camera1/camera_info</cameraInfoTopicName>
    </plugin>
  </gazebo>

  <!-- Gazebo Diff Drive Plugin -->
<gazebo>
  <plugin name="diff_drive_controller" filename="libgazebo_ros_diff_drive.so">
    <robotNamespace>/</robotNamespace>
    <commandTopic>/cmd_vel</commandTopic>
    <odometryTopic>/odom</odometryTopic>
    <odometryFrame>odom</odometryFrame>
    <robotBaseFrame>base_link</robotBaseFrame>
    <wheelSeparation>0.5</wheelSeparation>
    <wheelDiameter>0.15</wheelDiameter>
    <publishWheelTF>true</publishWheelTF>
    <publishWheelJointState>true</publishWheelJointState>
    <publishOdomTF>true</publishOdomTF>
    <wheelAcceleration>10.0</wheelAcceleration>
    <wheelTorque>50.0</wheelTorque>
    <updateRate>200</updateRate>
    <leftJoint>st_joint</leftJoint>
    <rightJoint>sp_joint</rightJoint>
    <rosDebugLevel>na</rosDebugLevel>
    <odometrySource>encoder</odometrySource>
    <publishTf>1</publishTf>
  </plugin>
</gazebo>
<gazebo reference="xoay_link">
  <plugin name="xoay_link_controller" filename="libgazebo_ros_control.so">
    <robotNamespace>/</robotNamespace>
    <jointName>xoay_joint</jointName>
    <pid>10.0 0.0 0.0</pid>
  </plugin>
</gazebo>

<gazebo reference="tien_link">
  <plugin name="tien_link_controller" filename="libgazebo_ros_control.so">
    <robotNamespace>/</robotNamespace>
    <jointName>tien_joint</jointName>
    <pid>10.0 0.0 0.0</pid>
  </plugin>
</gazebo>

<gazebo reference="st_joint">
  <plugin name="st_joint_encoder" filename="libgazebo_ros_joint_state_publisher.so">
    <jointName>st_joint</jointName>
    <topicName>/st_joint/encoder</topicName>
  </plugin>
</gazebo>

<gazebo reference="sp_joint">
  <plugin name="sp_joint_encoder" filename="libgazebo_ros_joint_state_publisher.so">
    <jointName>sp_joint</jointName>
    <topicName>/sp_joint/encoder</topicName>
  </plugin>
</gazebo>

</robot>